<?xml version="1.0" encoding="UTF-8"?>
<!-- Generated by org.testng.reporters.JUnitReportReporter -->
<testsuite hostname="a-cdd622f9b4c14" name="tests.UsingAssertions" tests="1" failures="1" timestamp="30 Jun 2011 18:14:08 GMT" time="0.016" errors="0">
  <testcase name="testGoogleSearch" time="0.016" classname="tests.UsingAssertions">
    <failure type="java.lang.AssertionError" message="Error coming because of xyz reason expected:&lt;true&gt; but was:&lt;false&gt;">
      <![CDATA[java.lang.AssertionError: Error coming because of xyz reason expected:<true> but was:<false>
	at org.testng.Assert.fail(Assert.java:89)
	at org.testng.Assert.failNotEquals(Assert.java:480)
	at org.testng.Assert.assertTrue(Assert.java:37)
	at tests.UsingAssertions.testGoogleSearch(UsingAssertions.java:25)
	at sun.reflect.NativeMethodAccessorImpl.invoke0(Native Method)
	at sun.reflect.NativeMethodAccessorImpl.invoke(Unknown Source)
	at sun.reflect.DelegatingMethodAccessorImpl.invoke(Unknown Source)
	at java.lang.reflect.Method.invoke(Unknown Source)
	at org.testng.internal.MethodInvocationHelper.invokeMethod(MethodInvocationHelper.java:74)
	at org.testng.internal.Invoker.invokeMethod(Invoker.java:673)
	at org.testng.internal.Invoker.invokeTestMethod(Invoker.java:846)
	at org.testng.internal.Invoker.invokeTestMethods(Invoker.java:1170)
	at org.testng.internal.TestMethodWorker.invokeTestMethods(TestMethodWorker.java:125)
	at org.testng.internal.TestMethodWorker.run(TestMethodWorker.java:109)
	at org.testng.TestRunner.runWorkers(TestRunner.java:1125)
	at org.testng.TestRunner.privateRun(TestRunner.java:749)
	at org.testng.TestRunner.run(TestRunner.java:600)
	at org.testng.SuiteRunner.runTest(SuiteRunner.java:317)
	at org.testng.SuiteRunner.runSequentially(SuiteRunner.java:312)
	at org.testng.SuiteRunner.privateRun(SuiteRunner.java:274)
	at org.testng.SuiteRunner.run(SuiteRunner.java:223)
	at org.testng.SuiteRunnerWorker.runSuite(SuiteRunnerWorker.java:52)
	at org.testng.SuiteRunnerWorker.run(SuiteRunnerWorker.java:86)
	at org.testng.TestNG.runSuitesSequentially(TestNG.java:1031)
	at org.testng.TestNG.runSuitesLocally(TestNG.java:956)
	at org.testng.TestNG.run(TestNG.java:892)
	at org.testng.TestNG.privateMain(TestNG.java:1174)
	at org.testng.TestNG.main(TestNG.java:1138)
]]>
    </failure>
  </testcase>
</testsuite>
